2016-06-01 14:56:49,247 - octoprint.server - INFO - Starting 3DRaion 1.2.11.post23+g6f4ebff (master branch)
2016-06-01 14:56:49,298 - octoprint.plugin.core - INFO - Loading plugins from /home/pi/.raionpi/plugins, /home/pi/RaionPi/venv/lib/python2.7/site-packages/OctoPrint-1.2.11.post23_g6f4ebff-py2.7.egg/octoprint/plugins and installed plugin packages...
2016-06-01 14:56:50,178 - octoprint.plugins.discovery - INFO - pybonjour is not installed, Zeroconf Discovery won't be available
2016-06-01 14:56:50,180 - octoprint.plugin.core - INFO - Found 7 plugin(s) providing 7 mixin implementations, 5 hook handlers
2016-06-01 14:56:50,189 - octoprint.filemanager.storage - INFO - Initializing the file metadata for /home/pi/.raionpi/uploads...
2016-06-01 14:56:50,190 - octoprint.filemanager.storage - INFO - ... file metadata for /home/pi/.raionpi/uploads initialized successfully.
2016-06-01 14:56:53,020 - octoprint.util.pip - INFO - Found pip at /home/pi/RaionPi/venv/bin/pip, version is 8.1.2
2016-06-01 14:56:53,024 - octoprint.plugin.core - INFO - Initialized 7 plugin implementation(s)
2016-06-01 14:56:53,048 - octoprint.plugin.core - INFO - 7 plugin(s) registered with the system:
|  Announcement Plugin (bundled) = /home/pi/RaionPi/venv/lib/python2.7/site-packages/OctoPrint-1.2.11.post23_g6f4ebff-py2.7.egg/octoprint/plugins/announcements
|  CuraEngine (<= 15.04) (bundled) = /home/pi/RaionPi/venv/lib/python2.7/site-packages/OctoPrint-1.2.11.post23_g6f4ebff-py2.7.egg/octoprint/plugins/cura
|  Discovery (bundled) = /home/pi/RaionPi/venv/lib/python2.7/site-packages/OctoPrint-1.2.11.post23_g6f4ebff-py2.7.egg/octoprint/plugins/discovery
|  Plugin Manager (bundled) = /home/pi/RaionPi/venv/lib/python2.7/site-packages/OctoPrint-1.2.11.post23_g6f4ebff-py2.7.egg/octoprint/plugins/pluginmanager
|  Software Update (bundled) = /home/pi/RaionPi/venv/lib/python2.7/site-packages/OctoPrint-1.2.11.post23_g6f4ebff-py2.7.egg/octoprint/plugins/softwareupdate
|  TouchUIPP (0.3.3) = /home/pi/RaionPi/venv/local/lib/python2.7/site-packages/octoprint_touchui
|  Virtual Printer (bundled) = /home/pi/RaionPi/venv/lib/python2.7/site-packages/OctoPrint-1.2.11.post23_g6f4ebff-py2.7.egg/octoprint/plugins/virtual_printer
2016-06-01 14:56:53,055 - octoprint.filemanager - INFO - Adding backlog items from all storage types to analysis queue...
2016-06-01 14:56:53,058 - octoprint.filemanager - INFO - Added 0 items from storage type "local" to analysis queue
2016-06-01 14:56:53,059 - octoprint.server - INFO - Reset webasset folder /home/pi/.raionpi/generated/webassets...
2016-06-01 14:56:53,060 - octoprint.server - INFO - Reset webasset folder /home/pi/.raionpi/generated/.webassets-cache...
2016-06-01 14:56:53,913 - octoprint.plugins.discovery - INFO - Registered 3DRaion instance on raionpi3 for SSDP
2016-06-01 14:56:54,246 - octoprint.plugins.pluginmanager - INFO - Loaded plugin repository data from http://plugins.octoprint.org/plugins.json
2016-06-01 14:56:54,299 - octoprint.server - INFO - Listening on http://0.0.0.0:5000
2016-06-01 14:56:54,302 - octoprint.plugin - ERROR - Error while calling plugin announcements
Traceback (most recent call last):
  File "/home/pi/RaionPi/venv/local/lib/python2.7/site-packages/OctoPrint-1.2.11.post23_g6f4ebff-py2.7.egg/octoprint/plugin/__init__.py", line 204, in call_plugin
    result = getattr(plugin, method)(*args, **kwargs)
  File "/home/pi/RaionPi/venv/lib/python2.7/site-packages/OctoPrint-1.2.11.post23_g6f4ebff-py2.7.egg/octoprint/plugins/announcements/__init__.py", line 42, in on_after_startup
    self._fetch_all_channels()
  File "/home/pi/RaionPi/venv/lib/python2.7/site-packages/OctoPrint-1.2.11.post23_g6f4ebff-py2.7.egg/octoprint/plugins/announcements/__init__.py", line 208, in _fetch_all_channels
    channels = self._get_channel_configs(force=force)
  File "/home/pi/RaionPi/venv/lib/python2.7/site-packages/OctoPrint-1.2.11.post23_g6f4ebff-py2.7.egg/octoprint/plugins/announcements/__init__.py", line 191, in _get_channel_configs
    for key, config in configs.items():
AttributeError: 'NoneType' object has no attribute 'items'
2016-06-01 14:57:08,217 - octoprint.plugins.cura - INFO - Path to CuraEngine has not been configured yet or does not exist (currently set to None), Cura will not be selectable for slicing
2016-06-01 14:57:08,662 - octoprint - ERROR - Exception on /plugin/announcements/channels [GET]
Traceback (most recent call last):
  File "/home/pi/RaionPi/venv/local/lib/python2.7/site-packages/Flask-0.10.1-py2.7.egg/flask/app.py", line 1817, in wsgi_app
    response = self.full_dispatch_request()
  File "/home/pi/RaionPi/venv/local/lib/python2.7/site-packages/Flask-0.10.1-py2.7.egg/flask/app.py", line 1477, in full_dispatch_request
    rv = self.handle_user_exception(e)
  File "/home/pi/RaionPi/venv/local/lib/python2.7/site-packages/Flask-0.10.1-py2.7.egg/flask/app.py", line 1381, in handle_user_exception
    reraise(exc_type, exc_value, tb)
  File "/home/pi/RaionPi/venv/local/lib/python2.7/site-packages/Flask-0.10.1-py2.7.egg/flask/app.py", line 1475, in full_dispatch_request
    rv = self.dispatch_request()
  File "/home/pi/RaionPi/venv/local/lib/python2.7/site-packages/Flask-0.10.1-py2.7.egg/flask/app.py", line 1461, in dispatch_request
    return self.view_functions[rule.endpoint](**req.view_args)
  File "/home/pi/RaionPi/venv/local/lib/python2.7/site-packages/OctoPrint-1.2.11.post23_g6f4ebff-py2.7.egg/octoprint/server/util/flask.py", line 709, in decorated_view
    return flask.ext.login.login_required(func)(*args, **kwargs)
  File "/home/pi/RaionPi/venv/local/lib/python2.7/site-packages/Flask_Login-0.2.2-py2.7.egg/flask_login.py", line 637, in decorated_view
    return func(*args, **kwargs)
  File "/home/pi/RaionPi/venv/local/lib/python2.7/site-packages/Flask_Principal-0.3.5-py2.7.egg/flask_principal/__init__.py", line 198, in _decorated
    rv = f(*args, **kw)
  File "/home/pi/RaionPi/venv/lib/python2.7/site-packages/OctoPrint-1.2.11.post23_g6f4ebff-py2.7.egg/octoprint/plugins/announcements/__init__.py", line 105, in get_channel_data
    channel_data = self._fetch_all_channels(force=force)
  File "/home/pi/RaionPi/venv/lib/python2.7/site-packages/OctoPrint-1.2.11.post23_g6f4ebff-py2.7.egg/octoprint/plugins/announcements/__init__.py", line 208, in _fetch_all_channels
    channels = self._get_channel_configs(force=force)
  File "/home/pi/RaionPi/venv/lib/python2.7/site-packages/OctoPrint-1.2.11.post23_g6f4ebff-py2.7.egg/octoprint/plugins/announcements/__init__.py", line 191, in _get_channel_configs
    for key, config in configs.items():
AttributeError: 'NoneType' object has no attribute 'items'
2016-06-01 14:57:08,680 - octoprint.server.util.sockjs - INFO - New connection from client: 192.168.0.20
2016-06-01 14:57:12,027 - octoprint.util.pip - INFO - Found pip at /home/pi/RaionPi/venv/bin/pip, version is 8.1.2
2016-06-01 14:57:12,782 - octoprint.plugins.softwareupdate - INFO - Saved version cache to disk
2016-06-01 15:15:34,689 - octoprint.server.util.sockjs - INFO - Client connection closed: 192.168.0.20
2016-06-01 15:15:36,161 - octoprint.plugins.cura - INFO - Path to CuraEngine has not been configured yet or does not exist (currently set to None), Cura will not be selectable for slicing
2016-06-01 15:15:37,610 - octoprint.server.util.sockjs - INFO - New connection from client: 192.168.0.20
2016-06-01 15:15:37,940 - octoprint - ERROR - Exception on /plugin/announcements/channels [GET]
Traceback (most recent call last):
  File "/home/pi/RaionPi/venv/local/lib/python2.7/site-packages/Flask-0.10.1-py2.7.egg/flask/app.py", line 1817, in wsgi_app
    response = self.full_dispatch_request()
  File "/home/pi/RaionPi/venv/local/lib/python2.7/site-packages/Flask-0.10.1-py2.7.egg/flask/app.py", line 1477, in full_dispatch_request
    rv = self.handle_user_exception(e)
  File "/home/pi/RaionPi/venv/local/lib/python2.7/site-packages/Flask-0.10.1-py2.7.egg/flask/app.py", line 1381, in handle_user_exception
    reraise(exc_type, exc_value, tb)
  File "/home/pi/RaionPi/venv/local/lib/python2.7/site-packages/Flask-0.10.1-py2.7.egg/flask/app.py", line 1475, in full_dispatch_request
    rv = self.dispatch_request()
  File "/home/pi/RaionPi/venv/local/lib/python2.7/site-packages/Flask-0.10.1-py2.7.egg/flask/app.py", line 1461, in dispatch_request
    return self.view_functions[rule.endpoint](**req.view_args)
  File "/home/pi/RaionPi/venv/local/lib/python2.7/site-packages/OctoPrint-1.2.11.post23_g6f4ebff-py2.7.egg/octoprint/server/util/flask.py", line 709, in decorated_view
    return flask.ext.login.login_required(func)(*args, **kwargs)
  File "/home/pi/RaionPi/venv/local/lib/python2.7/site-packages/Flask_Login-0.2.2-py2.7.egg/flask_login.py", line 637, in decorated_view
    return func(*args, **kwargs)
  File "/home/pi/RaionPi/venv/local/lib/python2.7/site-packages/Flask_Principal-0.3.5-py2.7.egg/flask_principal/__init__.py", line 198, in _decorated
    rv = f(*args, **kw)
  File "/home/pi/RaionPi/venv/lib/python2.7/site-packages/OctoPrint-1.2.11.post23_g6f4ebff-py2.7.egg/octoprint/plugins/announcements/__init__.py", line 105, in get_channel_data
    channel_data = self._fetch_all_channels(force=force)
  File "/home/pi/RaionPi/venv/lib/python2.7/site-packages/OctoPrint-1.2.11.post23_g6f4ebff-py2.7.egg/octoprint/plugins/announcements/__init__.py", line 208, in _fetch_all_channels
    channels = self._get_channel_configs(force=force)
  File "/home/pi/RaionPi/venv/lib/python2.7/site-packages/OctoPrint-1.2.11.post23_g6f4ebff-py2.7.egg/octoprint/plugins/announcements/__init__.py", line 191, in _get_channel_configs
    for key, config in configs.items():
AttributeError: 'NoneType' object has no attribute 'items'
2016-06-01 15:15:55,579 - octoprint.plugins.cura - INFO - Path to CuraEngine has not been configured yet or does not exist (currently set to None), Cura will not be selectable for slicing
2016-06-01 15:15:55,702 - octoprint.server.util.sockjs - INFO - New connection from client: 192.168.0.20
2016-06-01 15:15:56,347 - octoprint.server.util.sockjs - INFO - Client connection closed: 192.168.0.20
2016-06-01 15:15:56,463 - octoprint.server.util.sockjs - INFO - New connection from client: 192.168.0.20
2016-06-01 15:15:56,634 - octoprint - ERROR - Exception on /plugin/announcements/channels [GET]
Traceback (most recent call last):
  File "/home/pi/RaionPi/venv/local/lib/python2.7/site-packages/Flask-0.10.1-py2.7.egg/flask/app.py", line 1817, in wsgi_app
    response = self.full_dispatch_request()
  File "/home/pi/RaionPi/venv/local/lib/python2.7/site-packages/Flask-0.10.1-py2.7.egg/flask/app.py", line 1477, in full_dispatch_request
    rv = self.handle_user_exception(e)
  File "/home/pi/RaionPi/venv/local/lib/python2.7/site-packages/Flask-0.10.1-py2.7.egg/flask/app.py", line 1381, in handle_user_exception
    reraise(exc_type, exc_value, tb)
  File "/home/pi/RaionPi/venv/local/lib/python2.7/site-packages/Flask-0.10.1-py2.7.egg/flask/app.py", line 1475, in full_dispatch_request
    rv = self.dispatch_request()
  File "/home/pi/RaionPi/venv/local/lib/python2.7/site-packages/Flask-0.10.1-py2.7.egg/flask/app.py", line 1461, in dispatch_request
    return self.view_functions[rule.endpoint](**req.view_args)
  File "/home/pi/RaionPi/venv/local/lib/python2.7/site-packages/OctoPrint-1.2.11.post23_g6f4ebff-py2.7.egg/octoprint/server/util/flask.py", line 709, in decorated_view
    return flask.ext.login.login_required(func)(*args, **kwargs)
  File "/home/pi/RaionPi/venv/local/lib/python2.7/site-packages/Flask_Login-0.2.2-py2.7.egg/flask_login.py", line 637, in decorated_view
    return func(*args, **kwargs)
  File "/home/pi/RaionPi/venv/local/lib/python2.7/site-packages/Flask_Principal-0.3.5-py2.7.egg/flask_principal/__init__.py", line 198, in _decorated
    rv = f(*args, **kw)
  File "/home/pi/RaionPi/venv/lib/python2.7/site-packages/OctoPrint-1.2.11.post23_g6f4ebff-py2.7.egg/octoprint/plugins/announcements/__init__.py", line 105, in get_channel_data
    channel_data = self._fetch_all_channels(force=force)
  File "/home/pi/RaionPi/venv/lib/python2.7/site-packages/OctoPrint-1.2.11.post23_g6f4ebff-py2.7.egg/octoprint/plugins/announcements/__init__.py", line 208, in _fetch_all_channels
    channels = self._get_channel_configs(force=force)
  File "/home/pi/RaionPi/venv/lib/python2.7/site-packages/OctoPrint-1.2.11.post23_g6f4ebff-py2.7.egg/octoprint/plugins/announcements/__init__.py", line 191, in _get_channel_configs
    for key, config in configs.items():
AttributeError: 'NoneType' object has no attribute 'items'
2016-06-01 15:01:45,283 - octoprint.server - INFO - Starting 3DRaion 1.2.11.post23+g6f4ebff (master branch)
2016-06-01 15:01:45,358 - octoprint.plugin.core - INFO - Loading plugins from /home/pi/.raionpi/plugins, /home/pi/RaionPi/venv/lib/python2.7/site-packages/OctoPrint-1.2.11.post23_g6f4ebff-py2.7.egg/octoprint/plugins and installed plugin packages...
2016-06-01 15:01:46,524 - octoprint.plugins.discovery - INFO - pybonjour is not installed, Zeroconf Discovery won't be available
2016-06-01 15:01:46,526 - octoprint.plugin.core - INFO - Found 7 plugin(s) providing 7 mixin implementations, 5 hook handlers
2016-06-01 15:01:46,534 - octoprint.filemanager.storage - INFO - Initializing the file metadata for /home/pi/.raionpi/uploads...
2016-06-01 15:01:46,535 - octoprint.filemanager.storage - INFO - ... file metadata for /home/pi/.raionpi/uploads initialized successfully.
2016-06-01 15:01:46,594 - octoprint.plugins.softwareupdate - INFO - Loaded version cache from disk
2016-06-01 15:18:00,200 - octoprint.util.pip - INFO - Found pip at /home/pi/RaionPi/venv/bin/pip, version is 8.1.2
2016-06-01 15:18:00,203 - octoprint.plugin.core - INFO - Initialized 7 plugin implementation(s)
2016-06-01 15:18:00,209 - octoprint.plugin.core - INFO - 7 plugin(s) registered with the system:
|  Announcement Plugin (bundled) = /home/pi/RaionPi/venv/lib/python2.7/site-packages/OctoPrint-1.2.11.post23_g6f4ebff-py2.7.egg/octoprint/plugins/announcements
|  CuraEngine (<= 15.04) (bundled) = /home/pi/RaionPi/venv/lib/python2.7/site-packages/OctoPrint-1.2.11.post23_g6f4ebff-py2.7.egg/octoprint/plugins/cura
|  Discovery (bundled) = /home/pi/RaionPi/venv/lib/python2.7/site-packages/OctoPrint-1.2.11.post23_g6f4ebff-py2.7.egg/octoprint/plugins/discovery
|  Plugin Manager (bundled) = /home/pi/RaionPi/venv/lib/python2.7/site-packages/OctoPrint-1.2.11.post23_g6f4ebff-py2.7.egg/octoprint/plugins/pluginmanager
|  Software Update (bundled) = /home/pi/RaionPi/venv/lib/python2.7/site-packages/OctoPrint-1.2.11.post23_g6f4ebff-py2.7.egg/octoprint/plugins/softwareupdate
|  TouchUIPP (0.3.3) = /home/pi/RaionPi/venv/local/lib/python2.7/site-packages/octoprint_touchui
|  Virtual Printer (bundled) = /home/pi/RaionPi/venv/lib/python2.7/site-packages/OctoPrint-1.2.11.post23_g6f4ebff-py2.7.egg/octoprint/plugins/virtual_printer
2016-06-01 15:18:00,211 - octoprint.filemanager - INFO - Adding backlog items from all storage types to analysis queue...
2016-06-01 15:18:00,220 - octoprint.filemanager - INFO - Added 0 items from storage type "local" to analysis queue
2016-06-01 15:18:00,222 - octoprint.server - INFO - Reset webasset folder /home/pi/.raionpi/generated/webassets...
2016-06-01 15:18:00,237 - octoprint.server - INFO - Reset webasset folder /home/pi/.raionpi/generated/.webassets-cache...
2016-06-01 15:18:00,978 - octoprint.plugins.pluginmanager - INFO - Loaded plugin repository data from disk, was still valid
2016-06-01 15:18:01,006 - octoprint.plugins.discovery - INFO - Registered 3DRaion instance on raionpi3 for SSDP
2016-06-01 15:18:01,009 - octoprint.server - INFO - Listening on http://0.0.0.0:5000
2016-06-01 15:18:01,053 - octoprint.plugin - ERROR - Error while calling plugin announcements
Traceback (most recent call last):
  File "/home/pi/RaionPi/venv/local/lib/python2.7/site-packages/OctoPrint-1.2.11.post23_g6f4ebff-py2.7.egg/octoprint/plugin/__init__.py", line 204, in call_plugin
    result = getattr(plugin, method)(*args, **kwargs)
  File "/home/pi/RaionPi/venv/lib/python2.7/site-packages/OctoPrint-1.2.11.post23_g6f4ebff-py2.7.egg/octoprint/plugins/announcements/__init__.py", line 42, in on_after_startup
    self._fetch_all_channels()
  File "/home/pi/RaionPi/venv/lib/python2.7/site-packages/OctoPrint-1.2.11.post23_g6f4ebff-py2.7.egg/octoprint/plugins/announcements/__init__.py", line 208, in _fetch_all_channels
    channels = self._get_channel_configs(force=force)
  File "/home/pi/RaionPi/venv/lib/python2.7/site-packages/OctoPrint-1.2.11.post23_g6f4ebff-py2.7.egg/octoprint/plugins/announcements/__init__.py", line 191, in _get_channel_configs
    for key, config in configs.items():
AttributeError: 'NoneType' object has no attribute 'items'
2016-06-01 15:18:01,230 - octoprint.server - INFO - Preemptively caching / for {'query_string': 'l10n=en', 'path': '/', 'base_url': 'http://192.168.0.23:5000/'}
2016-06-01 15:18:01,901 - octoprint.server.util.sockjs - INFO - New connection from client: 192.168.0.20
2016-06-01 15:18:02,258 - octoprint - ERROR - Exception on /plugin/announcements/channels [GET]
Traceback (most recent call last):
  File "/home/pi/RaionPi/venv/local/lib/python2.7/site-packages/Flask-0.10.1-py2.7.egg/flask/app.py", line 1817, in wsgi_app
    response = self.full_dispatch_request()
  File "/home/pi/RaionPi/venv/local/lib/python2.7/site-packages/Flask-0.10.1-py2.7.egg/flask/app.py", line 1477, in full_dispatch_request
    rv = self.handle_user_exception(e)
  File "/home/pi/RaionPi/venv/local/lib/python2.7/site-packages/Flask-0.10.1-py2.7.egg/flask/app.py", line 1381, in handle_user_exception
    reraise(exc_type, exc_value, tb)
  File "/home/pi/RaionPi/venv/local/lib/python2.7/site-packages/Flask-0.10.1-py2.7.egg/flask/app.py", line 1475, in full_dispatch_request
    rv = self.dispatch_request()
  File "/home/pi/RaionPi/venv/local/lib/python2.7/site-packages/Flask-0.10.1-py2.7.egg/flask/app.py", line 1461, in dispatch_request
    return self.view_functions[rule.endpoint](**req.view_args)
  File "/home/pi/RaionPi/venv/local/lib/python2.7/site-packages/OctoPrint-1.2.11.post23_g6f4ebff-py2.7.egg/octoprint/server/util/flask.py", line 709, in decorated_view
    return flask.ext.login.login_required(func)(*args, **kwargs)
  File "/home/pi/RaionPi/venv/local/lib/python2.7/site-packages/Flask_Login-0.2.2-py2.7.egg/flask_login.py", line 637, in decorated_view
    return func(*args, **kwargs)
  File "/home/pi/RaionPi/venv/local/lib/python2.7/site-packages/Flask_Principal-0.3.5-py2.7.egg/flask_principal/__init__.py", line 198, in _decorated
    rv = f(*args, **kw)
  File "/home/pi/RaionPi/venv/lib/python2.7/site-packages/OctoPrint-1.2.11.post23_g6f4ebff-py2.7.egg/octoprint/plugins/announcements/__init__.py", line 105, in get_channel_data
    channel_data = self._fetch_all_channels(force=force)
  File "/home/pi/RaionPi/venv/lib/python2.7/site-packages/OctoPrint-1.2.11.post23_g6f4ebff-py2.7.egg/octoprint/plugins/announcements/__init__.py", line 208, in _fetch_all_channels
    channels = self._get_channel_configs(force=force)
  File "/home/pi/RaionPi/venv/lib/python2.7/site-packages/OctoPrint-1.2.11.post23_g6f4ebff-py2.7.egg/octoprint/plugins/announcements/__init__.py", line 191, in _get_channel_configs
    for key, config in configs.items():
AttributeError: 'NoneType' object has no attribute 'items'
2016-06-01 15:18:13,045 - octoprint.server.util.sockjs - INFO - New connection from client: 192.168.0.20
2016-06-01 15:18:18,070 - octoprint.plugins.cura - INFO - Path to CuraEngine has not been configured yet or does not exist (currently set to None), Cura will not be selectable for slicing
2016-06-01 15:18:21,091 - octoprint - ERROR - Exception on /plugin/announcements/channels [GET]
Traceback (most recent call last):
  File "/home/pi/RaionPi/venv/local/lib/python2.7/site-packages/Flask-0.10.1-py2.7.egg/flask/app.py", line 1817, in wsgi_app
    response = self.full_dispatch_request()
  File "/home/pi/RaionPi/venv/local/lib/python2.7/site-packages/Flask-0.10.1-py2.7.egg/flask/app.py", line 1477, in full_dispatch_request
    rv = self.handle_user_exception(e)
  File "/home/pi/RaionPi/venv/local/lib/python2.7/site-packages/Flask-0.10.1-py2.7.egg/flask/app.py", line 1381, in handle_user_exception
    reraise(exc_type, exc_value, tb)
  File "/home/pi/RaionPi/venv/local/lib/python2.7/site-packages/Flask-0.10.1-py2.7.egg/flask/app.py", line 1475, in full_dispatch_request
    rv = self.dispatch_request()
  File "/home/pi/RaionPi/venv/local/lib/python2.7/site-packages/Flask-0.10.1-py2.7.egg/flask/app.py", line 1461, in dispatch_request
    return self.view_functions[rule.endpoint](**req.view_args)
  File "/home/pi/RaionPi/venv/local/lib/python2.7/site-packages/OctoPrint-1.2.11.post23_g6f4ebff-py2.7.egg/octoprint/server/util/flask.py", line 709, in decorated_view
    return flask.ext.login.login_required(func)(*args, **kwargs)
  File "/home/pi/RaionPi/venv/local/lib/python2.7/site-packages/Flask_Login-0.2.2-py2.7.egg/flask_login.py", line 637, in decorated_view
    return func(*args, **kwargs)
  File "/home/pi/RaionPi/venv/local/lib/python2.7/site-packages/Flask_Principal-0.3.5-py2.7.egg/flask_principal/__init__.py", line 198, in _decorated
    rv = f(*args, **kw)
  File "/home/pi/RaionPi/venv/lib/python2.7/site-packages/OctoPrint-1.2.11.post23_g6f4ebff-py2.7.egg/octoprint/plugins/announcements/__init__.py", line 105, in get_channel_data
    channel_data = self._fetch_all_channels(force=force)
  File "/home/pi/RaionPi/venv/lib/python2.7/site-packages/OctoPrint-1.2.11.post23_g6f4ebff-py2.7.egg/octoprint/plugins/announcements/__init__.py", line 208, in _fetch_all_channels
    channels = self._get_channel_configs(force=force)
  File "/home/pi/RaionPi/venv/lib/python2.7/site-packages/OctoPrint-1.2.11.post23_g6f4ebff-py2.7.egg/octoprint/plugins/announcements/__init__.py", line 191, in _get_channel_configs
    for key, config in configs.items():
AttributeError: 'NoneType' object has no attribute 'items'
2016-06-01 15:18:22,158 - octoprint.server.util.sockjs - INFO - New connection from client: 192.168.0.23
2016-06-01 15:34:30,539 - octoprint.server.util.sockjs - INFO - Client connection closed: 192.168.0.20
2016-06-01 16:19:38,101 - octoprint.server.util.sockjs - INFO - Client connection closed: 192.168.0.20
2016-06-01 16:19:40,227 - octoprint.plugins.cura - INFO - Path to CuraEngine has not been configured yet or does not exist (currently set to None), Cura will not be selectable for slicing
2016-06-01 16:19:40,758 - octoprint.server.util.sockjs - INFO - New connection from client: 192.168.0.20
2016-06-01 16:19:40,906 - octoprint - ERROR - Exception on /plugin/announcements/channels [GET]
Traceback (most recent call last):
  File "/home/pi/RaionPi/venv/local/lib/python2.7/site-packages/Flask-0.10.1-py2.7.egg/flask/app.py", line 1817, in wsgi_app
    response = self.full_dispatch_request()
  File "/home/pi/RaionPi/venv/local/lib/python2.7/site-packages/Flask-0.10.1-py2.7.egg/flask/app.py", line 1477, in full_dispatch_request
    rv = self.handle_user_exception(e)
  File "/home/pi/RaionPi/venv/local/lib/python2.7/site-packages/Flask-0.10.1-py2.7.egg/flask/app.py", line 1381, in handle_user_exception
    reraise(exc_type, exc_value, tb)
  File "/home/pi/RaionPi/venv/local/lib/python2.7/site-packages/Flask-0.10.1-py2.7.egg/flask/app.py", line 1475, in full_dispatch_request
    rv = self.dispatch_request()
  File "/home/pi/RaionPi/venv/local/lib/python2.7/site-packages/Flask-0.10.1-py2.7.egg/flask/app.py", line 1461, in dispatch_request
    return self.view_functions[rule.endpoint](**req.view_args)
  File "/home/pi/RaionPi/venv/local/lib/python2.7/site-packages/OctoPrint-1.2.11.post23_g6f4ebff-py2.7.egg/octoprint/server/util/flask.py", line 709, in decorated_view
    return flask.ext.login.login_required(func)(*args, **kwargs)
  File "/home/pi/RaionPi/venv/local/lib/python2.7/site-packages/Flask_Login-0.2.2-py2.7.egg/flask_login.py", line 637, in decorated_view
    return func(*args, **kwargs)
  File "/home/pi/RaionPi/venv/local/lib/python2.7/site-packages/Flask_Principal-0.3.5-py2.7.egg/flask_principal/__init__.py", line 198, in _decorated
    rv = f(*args, **kw)
  File "/home/pi/RaionPi/venv/lib/python2.7/site-packages/OctoPrint-1.2.11.post23_g6f4ebff-py2.7.egg/octoprint/plugins/announcements/__init__.py", line 105, in get_channel_data
    channel_data = self._fetch_all_channels(force=force)
  File "/home/pi/RaionPi/venv/lib/python2.7/site-packages/OctoPrint-1.2.11.post23_g6f4ebff-py2.7.egg/octoprint/plugins/announcements/__init__.py", line 208, in _fetch_all_channels
    channels = self._get_channel_configs(force=force)
  File "/home/pi/RaionPi/venv/lib/python2.7/site-packages/OctoPrint-1.2.11.post23_g6f4ebff-py2.7.egg/octoprint/plugins/announcements/__init__.py", line 191, in _get_channel_configs
    for key, config in configs.items():
AttributeError: 'NoneType' object has no attribute 'items'
